Workbook

Sheet 2022 Charity (2)
A1: Group | D1: Company | E1: Corporate Key | F1: User Name | G1: Password | H1: What City was i born in? | I1: Answer | J1: Email | K1: ACN | L1: abn | M1: TFN | N1: Established Date | O1: Director | P1: Review Date | Q1: Amount Owing | R1: Amount of Shares | S1: Shareholder | T1: Registered | U1: Principle Place of Business
A2: Charity | B2: XERO | D2: Homes of Hope Limited | E2: 99406654 | F2: homesofhopeltd | G2: Bl3ss3d. | H2: What City was I Born In? | I2: Adelaide | J2: hello@joii.org.au | K2: 643 194 156 | L2: 22 643 194 156 | M2: 639 296 766 | N2: 44047 | O2: David , David and Aaron | P2: 44294 | Q2: 0 | R2: Public | T2: OFFICE 6 / 2404 LOGAN ROAD EIGHT MILE PLAINS QLD 4113 | U2: 46 Aspire Street Rochedale Qld 4123
A3: Charity | B3: nothing | D3: Impact Homes Pty Ltd (formerly Whoa2Go) | E3: ordered | K3: 093 693 415 | L3: 25 093 693 415 | M3: 773 195 351 | N3: 44025 | O3: Aaron Glowka | P3: 13/07/2022 | Q3: 0 | R3: 100 | S3: Homes Of Hope | T3: OFFICE 6 / 2404 LOGAN ROAD EIGHT MILE PLAINS QLD 4113 | U3: 46 Aspire Street Rochedale Qld 4123
A4: Charity | B4: XERO | D4: Livin The Dream | E4: 72943215 | F4: livinthedream | G4: Bl3ss3d. | H4: What City was I Born In? | I4: Adelaide | J4: hello@joii.org.au | K4: 142 372 245 | L4: 95 142 372 245 | M4: 913 810 842 | N4: 40240 | O4: James Jonathan Harder | P4: 44988 | Q4: 688 | R4: 100 | S4: Homes Of Hope | T4: OFFICE 6 / 2404 LOGAN ROAD EIGHT MILE PLAINS QLD 4113 | U4: 46 Aspire Street Rochedale Qld 4123
A5: Charity | B5: XERO | D5: Love Your World | E5: ordered | K5: 158 841 180 | L5: 91 158 841 180 | M5: 942 944 937 | N5: 41066 | O5: David , David and Aaron | P5: 42892 | Q5: 0 | R5: Public | T5: OFFICE 6 / 2404 LOGAN ROAD EIGHT MILE PLAINS QLD 4114 | U5: 46 Aspire Street Rochedale Qld 4123
A6: Charity | B6: XERO | C6: Strike Off | D6: Next Steps Global | E6: 40617621 | F6: nextstepsglobalptyltd | G6: Bl3ss3d. | H6: What City was I Born In? | I6: Adelaide | J6: hello@joii.org.au | K6: 629 932 887 | L6: 13 629 932 887 | M6: 570 952 809 | N6: 43414 | O6: Robert harder | P6: 44845 | Q6: -82 | R6: 100 | S6: Homes Of Hope | T6: OFFICE 6 / 2404 LOGAN ROAD EIGHT MILE PLAINS QLD 4114 | U6: 46 Aspire Street Rochedale Qld 4123
A7: Charity | B7: XERO | C7: Strike Off | D7: The Promise Qld | E7: ordered | K7: 158 275 640 | L7: 53 158 275 640 | M7: 935 906 938 | N7: 41187 | O7: Rachel Harder | P7: 45204 | Q7: 276 | R7: 100 | S7: Love Your World | T7: OFFICE 6 / 2404 LOGAN ROAD EIGHT MILE PLAINS QLD 4114 | U7: 46 Aspire Street Rochedale Qld 4123
A9: Charity | B9: R and D | C9: Strike Off | D9: Money Maid (formerly Harder Money) | K9: 159 631 240 | L9: 77 159 631 240 | M9: 938 235 185 | N9: 25/07/2012 | O9: James Jonathan Harder | P9: 44767 | R9: 100 | S9: Money Matters 20, OPen Gold 16, Joii 25 adn Duncan Miller 39 | T9: OFFICE 6 / 2404 LOGAN ROAD EIGHT MILE PLAINS QLD 4114 | U9: OFFICE 6 / 2404 LOGAN ROAD EIGHT MILE PLAINS QLD 4114
A10: Charity | B10: R and D | C10: Want to close | D10: Money Matters | K10: 605 103 615 | L10: 63 605 103 615 | M10: 635 209 293 | N10: 42095 | O10: Aaron Glowka | P10: 45017 | R10: 100 | S10: Love Your World | T10: OFFICE 6 / 2404 LOGAN ROAD EIGHT MILE PLAINS QLD 4114 | U10: OFFICE 6 / 2404 LOGAN ROAD EIGHT MILE PLAINS QLD 4114

Sheet 2022 Team Harder (2)
A1: Group | C1: Company | D1: Corporate Key | E1: User Name | F1: Password | G1: What City was i born in? | H1: Answer | I1: Carry Forward losses | J1: Franking Balance | K1: Bank Name | L1: BSB | M1: Account | N1: ACN | O1: abn | P1: TFN | Q1: Established Date | R1: Director | S1: Review Date | T1: Amount Owing | U1: Amount of Shares | V1: Shareholder | W1: Registered | X1: Principle Place of Business | Y1: Activity | Z1: what to Do
A2: 485 | B2: MYOB | C2: A Clement Developments Qld | N2: 138 613 046 | O2: 95 138 613 046 | P2: 938 926 367 | Q2: 31/07/2009 | R2: Robert Harder | U2: 2 | V2: Andrew and Ruth | W2: OFFICE 6 / 2404 LOGAN ROAD EIGHT MILE PLAINS QLD 4113 | X2: 46 Aspire Street Rochedale Qld 4123 | Y2: this is for Andrews Family Trust | Z2: Close If Possible
A3: 485 | B3: nothing | C3: Harder Developments Pty Ltd | N3: 073 411 275 | O3: not registered | Q3: 26/03/1996 | R3: Robert Harder | S3: Not Keeping | U3: 2 | V3: Rachel Harder | W3: OFFICE 6 / 2404 LOGAN ROAD EIGHT MILE PLAINS QLD 4113 | X3: 46 Aspire Street Rochedale Qld 4123 | Y3: old trustee th eharder family trust and did some share trading | Z3: Close If Possible
A4: Deregister | C4: JRKA Pty Ltd | I4: Deregister this company | N4: 635 352 671
A5: Team Harder | B5: XERO | C5: Gen2612 | K5: Gen2612 | L5: 84435 | M5: 767243550 | N5: 658 463 659 | O5: 47 658 463 659 | P5: 605 934 566 | Q5: 31/03/2022 | R5: Rachel harder | S5: 31/03/2023 | T5: 0 | U5: 100 | V5: ATF Team Harder Family Trust | W5: OFFICE 6 / 2404 LOGAN ROAD EIGHT MILE PLAINS QLD 4113 | X5: 160 ALPERTON ROAD , BURBANK QLD 4156 , Australia | Y5: Bucket Company
A6: Team Harder | B6: nothing | C6: Harder Family | D6: 13631732 | E6: harderfamilyrach | F6: Bl3ss3d. | G6: What City was i born in? | H6: Adelaide | N6: 159 632 087 | O6: 71 159 632 087 | P6: 939 058 021 | Q6: 25/07/2012 | R6: Rachel harder | S6: 45132 | T6: 0 | U6: 100 | V6: Rachel Harder | W6: OFFICE 6 / 2404 LOGAN ROAD EIGHT MILE PLAINS QLD 4113 | X6: 160 ALPERTON ROAD , BURBANK QLD 4156 , Australia | Y6: Trustee for The Harder Family Trust
A7: Team Harder | B7: XERO | C7: Harder Family ATF The Harder Family Trust | K7: The Harder Family Trust | L7: 084 435 | M7: 239941312 | O7: 20 459 034 329 | P7: 77 583 528 | Y7: Family Trust
A8: Team Harder | C8: Prov1322 Global | N8: 658 602 478 | O8: 34 658 602 478 | P8: 606 189 260 | Q8: 44716 | R8: Rachel Harder | S8: 45081 | T8: 0 | U8: 100 | V8: Rachel Harder | W8: OFFICE 6 / 2404 LOGAN ROAD EIGHT MILE PLAINS QLD 4113 | X8: 160 ALPERTON ROAD , BURBANK QLD 4156 , Australia
A9: Team Harder | B9: XERO | C9: Prov1322 Global ATF Team Harder Family Trust | K9: Team Harder Family Trust | L9: 084 435 | M9: 959276787 | O9: 94 633 472 433 | P9: 605 725 602 | Y9: Family Trust
A10: Team Harder | B10: XERO | C10: LATL | D10: 82704061 | E10: hello@lyw.org.au | F10: Bl3ss3d. | G10: What City was i born in? | H10: Adelaide | K10: LATL | L10: 084 435 | M10: 711090276 | N10: 145 576 138 | O10: 68 145 576 138 | P10: 918 281 149 | Q10: 40245 | R10: Rachel harder | S10: 44993 | T10: 0 | U10: 100 | V10: ATF The Harder Family Trust | W10: OFFICE 6 / 2404 LOGAN ROAD EIGHT MILE PLAINS QLD 4113 | X10: 160 ALPERTON ROAD , BURBANK QLD 4156 , Australia | Y10: Bucket Company
A11: Team Harder | C11: Robert Harder | O11: 93 373 928 858 | P11: 173 955 316
A12: Team Harder | C12: Rachel Harder | P12: 171 927 425
A13: Team Harder | C13: Jared Harder
A14: Team Harder | C14: Grace Harder
A15: Team Harder | C15: Sophie Harder
A16: Team Harder Super Fund GROUP | C16: Team Harder | N16: 645 359 495 | Q16: 23/10/2020 | R16: Rob and Rach | S16: 45222 | T16: 620 | U16: 100 | V16: Robert and Rachel | W16: OFFICE 6 / 2404 LOGAN ROAD EIGHT MILE PLAINS QLD 4113 | X16: OFFICE 6 / 2404 LOGAN ROAD EIGHT MILE PLAINS QLD 4113
A17: Team Harder Super Fund GROUP | B17: Dave | C17: Team Harder ATF Team Harder Super Fund | K17: Team Harder Super Fund | L17: 083 052 | M17: 304656703 | O17: 17 209 120 631 | P17: 534 254 470
A18: Team Harder Super Fund GROUP | B18: nothing | C18: Team Harder Super Investments | K18: Team Harder Super Investments | L18: 084 435 | M18: 259449309 | N18: 658 706 597 | O18: 32 658 706 597 | P18: 608 117 219 | Q18: 44662 | R18: Rachel Harder | S18: 45027 | T18: 0 | U18: 100 | V18: ATF Team Harder Super Fund | W18: OFFICE 6 / 2404 LOGAN ROAD EIGHT MILE PLAINS QLD 4113 | X18: 160 ALPERTON ROAD , BURBANK QLD 4156 , Australia | Y18: Investment for Super Fund
A19: Team Harder Super Fund GROUP | B19: MYOB | C19: AR Clement Investments | D19: ordered | K19: Team Harder Super Investments | L19: 084 435 | M19: 259449309 | N19: 145 575 659 | O19: 42 145 575 659 | P19: 918 280 369 | Q19: 40393 | R19: Rachel harder | S19: 45141 | T19: 0 | W19: OFFICE 6 / 2404 LOGAN ROAD EIGHT MILE PLAINS QLD 4113 | X19: 160 ALPERTON ROAD , BURBANK QLD 4156 , Australia | Y19: this is to do developments in going forward
A20: Team Harder Super Fund GROUP | B20: MYOB | C20: JRANDL Pty Ltd | D20: ordered | K20: JRANDL | L20: 084 435 | M20: 239209244 | N20: 610 667 555 | O20: 55 610 667 555 | P20: 977 018 668 | Q20: 42410 | R20: Rachel Harder | S20: 44967 | T20: 620 | U20: 4300000 | V20: Team Harder Super Investments | W20: OFFICE 6 / 2404 LOGAN ROAD EIGHT MILE PLAINS QLD 4113 | X20: 160 ALPERTON ROAD , BURBANK QLD 4156 , Australia | Y20: grouping THSI
A21: Team Harder Super Fund GROUP | B21: XERO | C21: W2G Assets | D21: 87081049 | E21: w2gasset | F21: Bl3ss3d. | G21: What City was I Born In? | H21: Adelaide | I21: hello@joii.org.au | J21: 092 659 688 | K21: 59 092 659 688 | L21: 726 881 624 | M21: 36655 | N21: 092 659 688 | O21: 59 092 659 688 | P21: 726 881 624 | Q21: 36655 | R21: Rachel Harder | S21: 45055 | T21: 276 | U21: 1000 | V21: Love Your World | W21: OFFICE 6 / 2404 LOGAN ROAD EIGHT MILE PLAINS QLD 4114 | X21: 160 ALPERTON ROAD , BURBANK QLD 4156 , Australia
C22: Property Alternative (AUS) Pty Ltd | N22: 610 974 019 | O22: 34 610 974 019 | P22: 986 555 939 | Q22: 25/02/2016 | R22: Robert Harder
P26: Harder Family
C32: 1432010
C33: 142406
C34: =C32+C33 -> 1574416

Sheet StatementImportTemplate.en-US
A1: *Date | B1: *Amount | C1: Payee | D1: Description | E1: Reference | F1: Check Number

Sheet Co Invest Homes
B1: All Companies
J2: Loan Agreement | K2: Things that must be filed | L2: 2024
B3: Co Invest Homes Pty Ltd | J3: Security Deed | K3: If is a discresionary trust , need to make the trust distribution every year before 30th June
B4: ACN: | C4: 691 269 333 | D4: ABN: | E4: 31691269333 | G4: TFN: | H4: 241641326 | J4: Company Setup | K4: All Bank Statement for the year
B5: Date Incorporated | C5: 45924 | F5: Shares on Issue | G5: 100 | J5: Solvency ASIC | K5: all assets purchases receipts
B6: Purpose: | C6: Co Invest into Homes | F6: Is it a Trustee | J6: Constitution | K6: all sales of assets
B7: Trust Name / Trustee | J7: Members | K7: all distribution if company
B8: Registered office | C8: 160 Alperton Road, Burbank QLD 4156 | F8: Principal place of business | J8: Structure | K8: all company minutes
D9: From | J9: ATO Tax Return | K9: ASIC showing company info on 30th june
B10: Current Director | C10: Rachel Anne Harder | D10: Jake Stanley Baird | J10: Asset | K10: All ASIC Documents
B11: Current Secretary | C11: Rachel Anne Harder | J11: Dividends | K11: Company Tax Return
J12: EOY ATO | K12: Company ATO due
B13: Does this Company have Loans | C13: No | F13: Is there loan documents in place | G13: No | J13: Registered Office
E14: Shares | F14: Beneficially Held | J14: Officers
B15: Current Shareholdings | C15: The Promise QLD | D15: Ordinary | E15: 67 | F15: Yes | G15: The Promise Family Trust | J15: Bank Statements
C16: The Promise QLD | D16: Class A | E16: 322 | F16: Yes | G16: The Promise Family Trust
C17: The Promise QLD | D17: Ordinary | E17: 67 | F17: Yes | G17: The Promise Family Trust
C18: The Promise QLD | D18: Class A | E18: 322 | F18: Yes | G18: The Promise Family Trust
J20: Minutes
B21: Current Bank Accounts | C21: Bank | D21: BSB | E21: Account | F21: Date Opened | J21: Distribution
C22: Westpac | D22: 034-093 | E22: 958183 | F22: 13.11.2025 | J22: EOY ASIC
J23: PPSR
J24: Tax Consolidation
J25: Trust Deed
B28: Folder Storage | C28: Co Invest Homes | D28: Abbreviation | E28: CIH
B30: Company Register | C30: Type | D30: Folder | E30: Date | F30: Manual | G30: Electronicaly Stored | H30: By Whom
D31: =VLOOKUP(C31,'Document Type'!$B$6:$C$34,2,FALSE) -> #N/A
D32: =VLOOKUP(C32,'Document Type'!$B$6:$C$34,2,FALSE) -> #N/A
D33: =VLOOKUP(C33,'Document Type'!$B$6:$C$34,2,FALSE) -> #N/A
D34: =VLOOKUP(C34,'Document Type'!$B$6:$C$34,2,FALSE) -> #N/A
D35: =VLOOKUP(C35,'Document Type'!$B$6:$C$34,2,FALSE) -> #N/A
D36: =VLOOKUP(C36,'Document Type'!$B$6:$C$34,2,FALSE) -> #N/A
D37: =VLOOKUP(C37,'Document Type'!$B$6:$C$34,2,FALSE) -> #N/A
D38: =VLOOKUP(C38,'Document Type'!$B$6:$C$34,2,FALSE) -> #N/A
D39: =VLOOKUP(C39,'Document Type'!$B$6:$C$34,2,FALSE) -> #N/A
D40: =VLOOKUP(C40,'Document Type'!$B$6:$C$34,2,FALSE) -> #N/A
D41: =VLOOKUP(C41,'Document Type'!$B$6:$C$34,2,FALSE) -> #N/A
D42: =VLOOKUP(C42,'Document Type'!$B$6:$C$34,2,FALSE) -> #N/A
... D65: =VLOOKUP(C65,'Document Type'!$B$6:$C$34,2,FALSE) -> #N/A
B66: Certifcate of Registration | C66: Company Setup | D66: =VLOOKUP(C66,'Document Type'!$B$6:$C$34,2,FALSE) -> Company Setup | E66: 45924 | F66: no | G66: Certifcate of registration - Co Invest Homes.pdf | H66: Robert
...

Sheet Co Invest Capital
B1: All Companies
J2: Loan Agreement | K2: Things that must be filed | L2: 2024
B3: Co Invest Capital Pty Ltd | J3: Security Deed | K3: If is a discresionary trust , need to make the trust distribution every year before 30th June
B4: ACN: 691 268 452 | D4: ABN: | G4: TFN: | J4: Company Setup | K4: All Bank Statement for the year
B5: Date Incorporated | C5: 45924 | F5: Shares on Issue | G5: 100 | J5: Solvency ASIC | K5: all assets purchases receipts
B6: Purpose: | C6: Get an ACL Licence | F6: Is it a Trustee | J6: Constitution | K6: all sales of assets
B7: Trust Name / Trustee | J7: Members | K7: all distribution if company
B8: Registered office | C8: 160 Alperton Road, Burbank QLD 4156 | F8: Principal place of business | J8: Structure | K8: all company minutes
D9: From | J9: ATO Tax Return | K9: ASIC showing company info on 30th june
B10: Current Director | C10: Rachel Anne Harder | J10: Asset | K10: All ASIC Documents
B11: Current Secretary | C11: Rachel Anne Harder | J11: Dividends | K11: Company Tax Return
J12: EOY ATO | K12: Company ATO due
B13: Does this Company have Loans | C13: No | F13: Is there loan documents in place | G13: No | J13: Registered Office
E14: Shares | F14: Beneficially Held | J14: Officers
B15: Current Shareholdings | C15: The Promise QLD | E15: 100 | F15: Yes | J15: Bank Statements
J16: Minutes
B17: Current Bank Accounts | C17: Bank | D17: BSB | E17: Account | F17: Date Opened | J17: Distribution
J18: EOY ASIC
J19: PPSR
J20: Tax Consolidation
J21: Trust Deed
B24: Folder Storage | C24: Co Invest Capital | D24: Abbreviation | E24: CIC
B26: Company Register | C26: Type | D26: Folder | E26: Date | F26: Manual | G26: Electronicaly Stored | H26: By Whom
D27: =VLOOKUP(C27,'Document Type'!$B$6:$C$34,2,FALSE) -> #N/A
D28: =VLOOKUP(C28,'Document Type'!$B$6:$C$34,2,FALSE) -> #N/A
D29: =VLOOKUP(C29,'Document Type'!$B$6:$C$34,2,FALSE) -> #N/A
D30: =VLOOKUP(C30,'Document Type'!$B$6:$C$34,2,FALSE) -> #N/A
D31: =VLOOKUP(C31,'Document Type'!$B$6:$C$34,2,FALSE) -> #N/A
D32: =VLOOKUP(C32,'Document Type'!$B$6:$C$34,2,FALSE) -> #N/A
D33: =VLOOKUP(C33,'Document Type'!$B$6:$C$34,2,FALSE) -> #N/A
D34: =VLOOKUP(C34,'Document Type'!$B$6:$C$34,2,FALSE) -> #N/A
D35: =VLOOKUP(C35,'Document Type'!$B$6:$C$34,2,FALSE) -> #N/A
D36: =VLOOKUP(C36,'Document Type'!$B$6:$C$34,2,FALSE) -> #N/A
D37: =VLOOKUP(C37,'Document Type'!$B$6:$C$34,2,FALSE) -> #N/A
D38: =VLOOKUP(C38,'Document Type'!$B$6:$C$34,2,FALSE) -> #N/A
... D61: =VLOOKUP(C61,'Document Type'!$B$6:$C$34,2,FALSE) -> #N/A
B62: Certifcate of Registration | C62: Company Setup | D62: =VLOOKUP(C62,'Document Type'!$B$6:$C$34,2,FALSE) -> Company Setup | E62: 45924 | F62: no | G62: Certificate of Registration - Co Invest Capital.pdf | H62: Robert
B64: Register of Members
B65: Date | C65: Issue, transfer,share split, buy back or Cancelation | D65: Class of Share | E65: Certification Number | F65: Serial Number From | G65: Serial Number To | H65: Number of Shares Aquired | I65: Trf'd to / Trf'd from | J65: Amount Paid Per Share | K65: Amount Unpaid per Share | L65: Fully Paid? (Y/N) | M65: Total Number os Shares Held | N65: Total Amount paid fo the shares | O65: Are the Shares Benedicially Held | P65: Owner / Buyer / Seller | Q65: ASIC Document Number
B92: 45924 | C92: Issue | D92: Ordinary | E92: 1 | F92: 1 | G92: 1 | H92: 100 | J92: 0.01 | K92: 0 | L92: Y | M92: 100 | N92: 1 | O92: Y | P92: The Promise QLD ATF The Promise Family Trust
...

Sheet W2G
B1: All Companies
J2: Loan Agreement | K2: Things that must be filed | L2: 2024
B3: W2G Assets Pty Ltd | J3: Security Deed | K3: If is a discresionary trust , need to make the trust distribution every year before 30th June
B4: ACN: | C4: 092 659 688 | D4: ABN: | E4: 59 092 659 688 | G4: TFN: | H4: 726 881 624 | J4: Company Setup | K4: All Bank Statement for the year
B5: Date Incorporated | C5: 36655 | F5: Shares on Issue | G5: 1000 | J5: Solvency ASIC | K5: all assets purchases receipts
B6: Purpose: | F6: Is it a Trustee | G6: No | J6: Constitution | K6: all sales of assets
B7: Trust Name / Trustee | J7: Members | K7: all distribution if company
B8: Registered office | C8: MAGNUS BUSINESS ADVISERS AND ACCOUNTANTS, UNIT 10 , 39 OLD CLEVELAND ROAD , CAPALABA QLD 4157 | F8: Principal place of business | G8: 160 Alperton Road, Burbank QLD 4156 | J8: Structure | K8: all company minutes
D9: From | J9: ATO Tax Return | K9: ASIC showing company info on 30th june
B10: Current Director | C10: Rachel Anne Harder | D10: 36655 | J10: Asset | K10: All ASIC Documents
B11: Current Secretary | C11: Rachel Anne Harder | D11: 40875 | J11: Dividends | K11: Company Tax Return
J12: EOY ATO | K12: Company ATO due
B13: Does this Company have Loans | C13: Yes | F13: Is there loan documents in place | G13: Yes | J13: Registered Office
E14: Shares | F14: Beneficially Held | J14: Officers
B15: Current Shareholdings | C15: Team Harder Super Investments Pty Ltd | E15: 1000 | F15: Yes | J15: Bank Statements
J16: Minutes
B17: Current Bank Accounts | C17: Bank | D17: BSB | E17: Account | F17: Date Opened | J17: Distribution
C18: NAB | D18: 084-435 | E18: 513642009 | F18: 44768 | J18: EOY ASIC
C19: NAB Trade | D19: 083-052 | E19: 304658188 | J19: PPSR
J20: Tax Consolidation
J21: Trust Deed
B24: Folder Storage | C24: W2G Assets | D24: Abbreviation | E24: W2G
B26: Company Register | C26: Type | D26: Folder | E26: Date | F26: Manual | G26: Electronicaly Stored | H26: By Whom | J26: Things to Do
B27: EOY ASIC FY24 | C27: EOY ASIC | D27: =VLOOKUP(C27,'Document Type'!$B$6:$C$34,2,FALSE) -> General | E27: 45471 | G27: EOY ASIC FY24 W2G
B28: EOY ATO FY24 | C28: EOY ATO | D28: =VLOOKUP(C28,'Document Type'!$B$6:$C$34,2,FALSE) -> General | E28: 45471 | G28: EOY ATO FY24 W2G
B29: BOQ Acc 21446327 CLOSED | C29: Bank Statements | D29: =VLOOKUP(C29,'Document Type'!$B$6:$C$34,2,FALSE) -> General | G29: W2G BOQ 21446327 FY24 CLOSED 28.12.23
B30: BOQ Loan Acc 23084038 CLOSED | C30: Bank Statements | D30: =VLOOKUP(C30,'Document Type'!$B$6:$C$34,2,FALSE) -> General | G30: W2G BOQ Loan 23084038 FY24 CLOSED 08.12.23
B31: Certificate of Registration | C31: Company Setup | D31: =VLOOKUP(C31,'Document Type'!$B$6:$C$34,2,FALSE) -> Company Setup | E31: 36655 | G31: Certificate of Registration W2G
B32: Constituition | C32: Constitution | D32: =VLOOKUP(C32,'Document Type'!$B$6:$C$34,2,FALSE) -> Constitution | E32: 36655 | G32: Constituition W2G
B33: Share Certificate | C33: Members | D33: =VLOOKUP(C33,'Document Type'!$B$6:$C$34,2,FALSE) -> Register of Members | E33: 36655 | G33: Share Certificate W2G
B34: Resignation of Director | C34: Officers | D34: =VLOOKUP(C34,'Document Type'!$B$6:$C$34,2,FALSE) -> General | E34: 44497 | G34: Resignation of Director RH W2G
B35: Change of Address | C35: ASIC Docs | D35: =VLOOKUP(C35,'Document Type'!$B$6:$C$34,2,FALSE) -> General | E35: 44159 | G35: Change of Address W2G
D36: =VLOOKUP(C36,'Document Type'!$B$6:$C$34,2,FALSE) -> #N/A
D37: =VLOOKUP(C37,'Document Type'!$B$6:$C$34,2,FALSE) -> #N/A
D38: =VLOOKUP(C38,'Document Type'!$B$6:$C$34,2,FALSE) -> #N/A
D39: =VLOOKUP(C39,'Document Type'!$B$6:$C$34,2,FALSE) -> #N/A
D40: =VLOOKUP(C40,'Document Type'!$B$6:$C$34,2,FALSE) -> #N/A
D41: =VLOOKUP(C41,'Document Type'!$B$6:$C$34,2,FALSE) -> #N/A
D42: =VLOOKUP(C42,'Document Type'!$B$6:$C$34,2,FALSE) -> #N/A
D43: =VLOOKUP(C43,'Document Type'!$B$6:$C$34,2,FALSE) -> #N/A
...

Sheet THSI
B1: All Companies
J2: Loan Agreement | K2: Things that must be filed | L2: 2024
B3: Team Harder Super Investments | J3: Security Deed | K3: If is a discresionary trust , need to make the trust distribution every year before 30th June
B4: ACN: | C4: 658 706 597 | D4: ABN: | E4: 32 658 706 597 | G4: TFN: | H4: 608 117 219 | J4: Company Setup | K4: All Bank Statement for the year
B5: Date Incorporated | C5: 44662 | F5: Shares on Issue | G5: 100 | J5: Solvency ASIC | K5: all assets purchases receipts
B6: Purpose: | F6: Is it a Trustee | G6: No | J6: Constitution | K6: all sales of assets
B7: Trust Name / Trustee | J7: Members | K7: all distribution if company
B8: Registered office | C8: MAGNUS BUSINESS ADVISERS AND ACCOUNTANTS, UNIT 10 , 39 OLD CLEVELAND ROAD , CAPALABA QLD 4157 | F8: Principal place of business | G8: 160 Alperton Road, Burbank QLD 4156 | J8: Structure | K8: all company minutes
D9: From | J9: ATO Tax Return | K9: ASIC showing company info on 30th june
B10: Current Director | C10: Rachel Anne Harder | D10: 44662 | J10: Asset | K10: All ASIC Documents
B11: Current Secretary | C11: Rachel Anne Harder | D11: 44662 | J11: Dividends | K11: Company Tax Return
J12: EOY ATO | K12: Company ATO due
B13: Does this Company have Loans | C13: No | F13: Is there loan documents in place | G13: No | J13: Registered Office
E14: Shares | F14: Beneficially Held | J14: Officers
B15: Current Shareholdings | C15: Prov1322 Global Pty Ltd | E15: 100 | F15: No | J15: Bank Statements
J16: Minutes
B17: Current Bank Accounts | C17: Bank | D17: BSB | E17: Account | F17: Date Opened | J17: Distribution
C18: NAB | D18: 084-435 | E18: 259449309 | F18: 44671 | J18: EOY ASIC
C19: NAB Trade | D19: 083-052 | E19: 305422840 | J19: PPSR
C20: Westpac | J20: Tax Consolidation
J21: Trust Deed
B24: Folder Storage | C24: Team Harder Super Investments | D24: Abbreviation | E24: THSI
B26: Company Register | C26: Type | D26: Folder | E26: Date | F26: Manual | G26: Electronicaly Stored | H26: By Whom | J26: Things to Do
B27: EOY ASIC FY24 | C27: EOY ASIC | D27: =VLOOKUP(C27,'Document Type'!$B$6:$C$34,2,FALSE) -> General | E27: 45471 | G27: EOY ASIC FY24 THSI
B28: EOY ATO FY24 | C28: EOY ATO | D28: =VLOOKUP(C28,'Document Type'!$B$6:$C$34,2,FALSE) -> General | E28: 45471 | G28: EOY ATO FY24 THIS
B29: Corporate Key | C29: Corporate Key | D29: General | E29: 45100 | G29: Corporate Key THIS
B30: EOY ASIC FY23 | C30: EOY ASIC | D30: =VLOOKUP(C30,'Document Type'!$B$6:$C$34,2,FALSE) -> General | E30: 45107 | G30: EOY ASIC FY23 THIS
B31: EOY ATO FY23 | C31: EOY ATO | D31: =VLOOKUP(C31,'Document Type'!$B$6:$C$34,2,FALSE) -> General | E31: 45107 | G31: EOY ATO FY23 THIS
B32: Change to Register of Members | C32: Members | D32: =VLOOKUP(C32,'Document Type'!$B$6:$C$34,2,FALSE) -> Register of Members | E32: 44698 | G32: Change to Register of Members THIS
B33: Registered Address | C33: ASIC Docs | D33: =VLOOKUP(C33,'Document Type'!$B$6:$C$34,2,FALSE) -> General | E33: 44698 | G33: Registered Office Multiplace THIS
B34: Resolution of Expenditure | C34: Minutes | D34: =VLOOKUP(C34,'Document Type'!$B$6:$C$34,2,FALSE) -> Minutes | E34: 45283 | G34: Resolution of Expenditure THIS
B35: EOFY 24 Dividend Resolution | D35: General | E35: 45842 | G35: [SIGNED] 2024 Dividend Resolution - W2G ASSETS PTY LTD | H35: Rachel
B36: EOFY 24 Financials | D36: General | E36: 45842 | G36: [SIGNED] Team Harder Super Investments Pty Ltd - Consolidated Financials 2024 | H36: rachel
B37: EOFY24 Tax Return | D37: General | E37: 45842 | G37: [SIGNED] Team Harder Super Investments Pty Ltd - Consolidated Tax Return 2024 | H37: Rachel
B38: Annual Company Statement | D38: General | E38: 45813
B39: PAYG - June 2025 | D39: General | E39: 45862 | G39: [SIGNED] Team Harder Super Investments Pty Ltd - PAYGIN June 2025 | H39: Rachel
D40: =VLOOKUP(C40,'Document Type'!$B$6:$C$34,2,FALSE) -> #N/A
D41: =VLOOKUP(C41,'Document Type'!$B$6:$C$34,2,FALSE) -> #N/A
D42: =VLOOKUP(C42,'Document Type'!$B$6:$C$34,2,FALSE) -> #N/A
D43: =VLOOKUP(C43,'Document Type'!$B$6:$C$34,2,FALSE) -> #N/A
...

Sheet Team Harder Family Trust
B1: All Companies
B3: Prov1322 Global ATF Team Harder Family Trust | J3: Things to Do:
B4: ACN: | D4: ABN: | E4: 94 633 472 433 | G4: TFN: | H4: 605 725 602 | J4: Need Structure Group
B5: Date Incorporated | C5: 44383 | F5: Shares on Issue | J5: Share Purchase
B6: Purpose: | C6: To Act as a Trust for Prov1322 | F6: Is it a Trustee | G6: No | J6: Gold Purchase
B7: Trust Name / Trustee | C7: Team Harder Family Trust | J7: Limeco Purchase
B8: Registered office | C8: MAGNUS BUSINESS ADVISERS AND ACCOUNTANTS, UNIT 10 , 39 OLD CLEVELAND ROAD , CAPALABA QLD 4157 | F8: Principal place of business | G8: 160 Alperton Road, Burbank QLD 4156 | J8: Tekna Purchase
D9: From | J9: Silver Purchase
B10: Current Director
B11: Current Secretary
B13: Does this Company have Loans | C13: No | F13: Is there loan documents in place | G13: No
E14: Shares | F14: Beneficially Held
B15: Current Shareholdings
B17: Current Bank Accounts | C17: Bank | D17: BSB | E17: Account | F17: Date Opened
C18: Westpac | D18: 034-076 | E18: 699669 | F18: 45282
C19: Westpac Trade | E19: 6864378 | F19: 45483
C20: NAB | D20: 084-436 | E20: 959276787 | F20: 44399
C21: NAB Trade | D21: 083-052 | E21: 305383521
B24: Folder Storage | C24: Team Harder Family Trust | D24: Abbreviation | E24: THFT
B26: Company Register | C26: Type | D26: Folder | E26: Date | F26: Manual | G26: Electronicaly Stored | H26: By Whom
B27: Harder Bloodline Trust Deed | C27: Trust Deed | D27: =VLOOKUP(C27,'Document Type'!$B$6:$C$34,2,FALSE) -> Trust Deed | E27: 44270 | G27: Harder Bloodline Trust Deed THFT | H27: Sophie Harder
B28: Harder Bloodline Trust Certified | C28: Trust Deed | D28: =VLOOKUP(C28,'Document Type'!$B$6:$C$34,2,FALSE) -> Trust Deed | E28: 44270 | G28: Harder Bloodline Trust Certified THFT | H28: Sophie Harder
B29: Bloodline Trust Name Change THFT | C29: Trust Deed | D29: =VLOOKUP(C29,'Document Type'!$B$6:$C$34,2,FALSE) -> Trust Deed | E29: 44641 | G29: Bloodline Name Change to THFT | H29: Sophie Harder
B30: Deed of Appointment and Removal | C30: Trust Deed | D30: =VLOOKUP(C30,'Document Type'!$B$6:$C$34,2,FALSE) -> Trust Deed | E30: 44642 | G30: Trustee Changed Rachel to Harder Dev THFT | H30: Sophie Harder
B31: Deed of Appointment and Removal | C31: Trust Deed | D31: =VLOOKUP(C31,'Document Type'!$B$6:$C$34,2,FALSE) -> Trust Deed | E31: 44658 | G31: Trustee Change Harder Dev to Prov1322 THFT | H31: Sophie Harder
B32: Loan Prov1322 to Gen2612 THFT | C32: Loan Agreement | D32: =VLOOKUP(C32,'Document Type'!$B$6:$C$34,2,FALSE) -> Loans and Security | E32: 44658 | G32: In folder in Loans and Security | H32: Sophie Harder
B33: Jared to Prov1322 THFT | C33: Loan Agreement | D33: =VLOOKUP(C33,'Document Type'!$B$6:$C$34,2,FALSE) -> Loans and Security | E33: 44658 | G33: In folder in Loans and Security | H33: Sophie Harder
B34: Grace to Prov1322 THFT | C34: Loan Agreement | D34: =VLOOKUP(C34,'Document Type'!$B$6:$C$34,2,FALSE) -> Loans and Security | E34: 44658 | G34: In folder in Loans and Security | H34: Sophie Harder
B35: Sophie to Prov1322 THFT | C35: Loan Agreement | D35: =VLOOKUP(C35,'Document Type'!$B$6:$C$34,2,FALSE) -> Loans and Security | E35: 44658 | G35: In folder in Loans and Security | H35: Sophie Harder
B36: Distribution Minute | C36: Distribution Minutes | D36: =VLOOKUP(C36,'Document Type'!$B$6:$C$34,2,FALSE) -> Minutes | E36: 44741 | G36: Distribution Minute 2022 THFT | H36: Sophie Harder
B37: Distribution Minute FY22 THFT | C37: Distribution Minutes | D37: =VLOOKUP(C37,'Document Type'!$B$6:$C$34,2,FALSE) -> Minutes | E37: 44742 | G37: Distribution Minute FY22 THFT
B38: Change of Company | C38: ASIC Docs | D38: =VLOOKUP(C38,'Document Type'!$B$6:$C$34,2,FALSE) -> General | E38: 44767 | G38: Change of Company Details THFT | H38: Sophie Harder
B39: Distribution Minute | C39: Distribution Minutes | D39: =VLOOKUP(C39,'Document Type'!$B$6:$C$34,2,FALSE) -> Minutes | E39: 45107 | G39: Distribution Minute 2023 THFT | H39: Sophie Harder
B40: 2023 - Team Harder Family Trust - Distribution Minute | C40: Distribution Minutes | D40: =VLOOKUP(C40,'Document Type'!$B$6:$C$34,2,FALSE) -> Minutes | E40: 45107 | G40: Distribution Minute FY23 THFT | H40: Sophie Harder
B41: This was because we couldn’t find orginal deed and sign resigned stating it was done then | C41: Trust Deed | D41: =VLOOKUP(C41,'Document Type'!$B$6:$C$34,2,FALSE) -> Trust Deed | E41: 45282 | G41: Deed of Variation of Discretionary Trust THFT | H41: Sophie Harder
B42: EOY ATO FY24 | C42: EOY ATO | D42: =VLOOKUP(C42,'Document Type'!$B$6:$C$34,2,FALSE) -> General | E42: 45471 | G42: EOY ATO FY24 Prov1322 ATF THFT | H42: Sophie Harder
B43: Distribution Minute FY24 THFT | C43: Distribution Minutes | D43: =VLOOKUP(C43,'Document Type'!$B$6:$C$34,2,FALSE) -> Minutes | E43: 45472 | G43: Distribution Minute FY24 THFT | H43: Sophie Harder
B44: Return of Gift Deed | C44: Return of Gift Deed | D44: =VLOOKUP(C44,'Document Type'!$B$6:$C$34,2,FALSE) -> Loans and Security | E44: 45108 | G44: Return of Gift Deed THFT | H44: Sophie Harder
B45: EOY NAB 959276787 FY22 | C45: Bank Statements | D45: =VLOOKUP(C45,'Document Type'!$B$6:$C$34,2,FALSE) -> General | E45: 45562 | G45: EOY NAB 959276787 FY22 THFT | H45: Rachel
B46: EOY NAB 959276787 FY23 | C46: Bank Statements | D46: =VLOOKUP(C46,'Document Type'!$B$6:$C$34,2,FALSE) -> General | E46: 45562 | G46: EOY NAB 959276787 FY23 THFT | H46: Rachel
...

Sheet Prov1322
A1: All Companies
I2: Loan Agreement | J2: Things that must be filed | K2: 2024
A3: Prov1322 Global Pty Ltd | I3: Security Deed | J3: If is a discresionary trust , need to make the trust distribution every year before 30th June
A4: ACN: | B4: 658 602 478 | C4: ABN: | D4: 34 658 602 478 | F4: TFN: | G4: 606 189 260 | I4: Company Setup | J4: All Bank Statement for the year
A5: Date Incorporated | B5: 44657 | E5: Shares on Issue | F5: 100 | I5: Solvency ASIC | J5: all assets purchases receipts
A6: Purpose: | B6: To act as Trustee for Team Harder Family Trust | E6: Is it a Trustee | F6: Yes | I6: Constitution | J6: all sales of assets
A7: Trust Name / Trustee | B7: Team Harder Family Trust | I7: Members | J7: all distribution if company
A8: Registered office | B8: MAGNUS BUSINESS ADVISERS AND ACCOUNTANTS, UNIT 10 , 39 OLD CLEVELAND ROAD , CAPALABA QLD 4157 | E8: Principal place of business | F8: 160 Alperton Road, Burbank QLD 4156 | I8: Structure | J8: all company minutes
C9: From | I9: ATO Tax Return | J9: ASIC showing company info on 30th june
A10: Current Director | B10: Rachel Anne Harder | C10: 44657 | I10: Asset | J10: All ASIC Documents
A11: Current Secretary | B11: Rachel Anne Harder | C11: 44657 | I11: Dividends | J11: Company Tax Return
I12: EOY ATO | J12: Company ATO due
A13: Does this Company have Loans | B13: No | E13: Is there loan documents in place | F13: No | I13: Registered Office
D14: Shares | E14: Beneficially Held | I14: Officers
A15: Current Shareholdings | B15: Rachel Harder | D15: 100 | E15: Yes | I15: Bank Statements
I16: Minutes
A17: Current Bank Accounts | B17: Bank | C17: BSB | D17: Account | E17: Date Opened | I17: Distribution
B18: NAB | I18: EOY ASIC
B19: Westpac | C19: 034-076 | D19: 699669 | E19: 45282 | I19: PPSR
I20: Tax Consolidation
I21: Trust Deed
A24: Folder Storage | B24: Prov1322 | C24: Abbreviation | D24: Prov1322
A26: Company Register | B26: Type | C26: Folder | D26: Date | E26: Manual | F26: Electronicaly Stored | G26: By Whom | I26: Things to Do
A27: EOY ATO FY24 | B27: EOY ATO | C27: =VLOOKUP(B27,'Document Type'!$B$6:$C$34,2,FALSE) -> General | D27: 45471 | F27: EOY ATO FY24 Prov1322
A28: EOY ASIC FY24 | B28: EOY ASIC | C28: =VLOOKUP(B28,'Document Type'!$B$6:$C$34,2,FALSE) -> General | D28: 45471 | F28: EOY ASIC FY24 Prov1322
A29: Certificate of Registration | B29: Company Setup | C29: =VLOOKUP(B29,'Document Type'!$B$6:$C$34,2,FALSE) -> Company Setup | D29: 44657 | F29: Certificate of Registration Prov1322
A30: Constituition | B30: Constitution | C30: =VLOOKUP(B30,'Document Type'!$B$6:$C$34,2,FALSE) -> Constitution | D30: 44657 | F30: Constitution Prov1322.pdf
A31: Corporate Key | B31: Corporate Key | C31: =VLOOKUP(B31,'Document Type'!$B$6:$C$34,2,FALSE) -> General | D31: 45100 | F31: Corporate Key Prov1322
A32: EOY ATO FY23 | B32: EOY ATO | C32: =VLOOKUP(B32,'Document Type'!$B$6:$C$34,2,FALSE) -> General | D32: 45107 | F32: EOY ATO FY23 Prov1322
A33: EOY ASIC FY23 | B33: EOY ASIC | C33: =VLOOKUP(B33,'Document Type'!$B$6:$C$34,2,FALSE) -> General | D33: 45107 | F33: EOY ASIC FY23 Prov1322
A34: Registered Office | B34: ASIC Docs | C34: =VLOOKUP(B34,'Document Type'!$B$6:$C$34,2,FALSE) -> General | D34: 44698 | F34: Registered Office Multiplace Prov1322
A35: Annual Solvency Minutes | B35: Minutes | C35: =VLOOKUP(B36,'Document Type'!$B$6:$C$34,2,FALSE) -> Register of Members | D35: 44657 | F35: Annual Solvency Minutes Prov1322
A36: Share Certificate | B36: Members | C36: Register of Members | D36: 44657 | F36: Share Certificate Rachel Harder Prov1322
A37: Resolution of Members | B37: Members | C37: =VLOOKUP(B37,'Document Type'!$B$6:$C$34,2,FALSE) -> Register of Members | D37: 44657 | F37: Resolution of Members Prov1322
A38: Register of Debentures | B38: Members | C38: =VLOOKUP(B38,'Document Type'!$B$6:$C$34,2,FALSE) -> Register of Members | D38: 44714 | F38: Register of Debentures Prov1322
A39: Register of Charges | B39: Members | C39: =VLOOKUP(B39,'Document Type'!$B$6:$C$34,2,FALSE) -> Register of Members | D39: 44714 | F39: Register of Charges Prov1322
A40: Officeholder Consent | B40: Members | C40: =VLOOKUP(B40,'Document Type'!$B$6:$C$34,2,FALSE) -> Register of Members | D40: 44714 | F40: Officeholder Consent Rachel Harder Prov1322
A41: Application for Shares | B41: Members | C41: =VLOOKUP(B41,'Document Type'!$B$6:$C$34,2,FALSE) -> Register of Members | D41: 44714 | F41: Application for Shares Rachel Harder Prov1322
A42: Register of Members | B42: Members | C42: =VLOOKUP(B42,'Document Type'!$B$6:$C$34,2,FALSE) -> Register of Members | D42: 44657 | F42: Register of Members Prov1322
A43: Change to Register of Members | B43: Members | C43: =VLOOKUP(B43,'Document Type'!$B$6:$C$34,2,FALSE) -> Register of Members | D43: 44698 | F43: Change of Register of Members Prov1322
...

Sheet Gen2612
A1: All Companies
A3: Gen2612 Pty Ltd | I3: Things to Do:
A4: ACN: | B4: 658 463 659 | C4: ABN: | D4: 47 658 463 659 | F4: TFN: | G4: 605 934 566 | I4: Need Structure Group
A5: Date Incorporated | B5: 44651 | E5: Shares on Issue | F5: 100
A6: Purpose: | E6: Is it a Trustee
A7: Trust Name / Trustee
A8: Registered office | B8: MAGNUS BUSINESS ADVISERS AND ACCOUNTANTS, UNIT 10 , 39 OLD CLEVELAND ROAD , CAPALABA QLD 4157 | E8: Principal place of business | F8: 160 Alperton Road, Burbank QLD 4156
C9: From
A10: Current Director | B10: Rachel Anne Harder | C10: 44651
A11: Current Secretary | B11: Rachel Anne Harder | C11: 44651
A13: Does this Company have Loans | B13: Yes | E13: Is there loan documents in place | F13: Yes
D14: Shares | E14: Beneficially Held
A15: Current Shareholdings | B15: Prov1322 Global Pty Ltd | D15: 100 | E15: No
A17: Current Bank Accounts | B17: Bank | C17: BSB | D17: Account | E17: Date Opened
B18: Westpac | C18: 034-076 | D18: 709783 | E18: 45356
B19: NAB | C19: 084-435 | D19: 767243550 | E19: 44658
A24: Folder Storage | B24: Gen2612 | C24: Abbreviation | D24: Gen2612
A26: Company Register | B26: Type | C26: Folder | D26: Date | E26: Manual | F26: Electronicaly Stored | G26: By Whom
A27: Application for Incorporation | B27: ASIC Docs | C27: =VLOOKUP(B27,'Document Type'!$B$6:$C$34,2,FALSE) -> General | D27: 44651 | F27: Application for Incorporation Gen2612
A28: Application for Shares | B28: Members | C28: =VLOOKUP(B28,'Document Type'!$B$6:$C$34,2,FALSE) -> Register of Members | D28: 44714 | F28: Applications for Shares Gen2612
A29: Certificate of Registration | B29: Company Setup | C29: =VLOOKUP(B29,'Document Type'!$B$6:$C$34,2,FALSE) -> Company Setup | D29: 44714 | F29: Certificate of Registration Gen212
A30: Commissioner of Tax | B30: Members | C30: =VLOOKUP(B30,'Document Type'!$B$6:$C$34,2,FALSE) -> Register of Members | D30: 44651 | F30: Letter to Commissioner of Tax Gen2612
A31: Constituition | B31: Constitution | C31: =VLOOKUP(B31,'Document Type'!$B$6:$C$34,2,FALSE) -> Constitution | D31: 44850 | F31: Constitution Gen2612.pdf
A32: Corporate Key | B32: Corporate Key | C32: =VLOOKUP(B32,'Document Type'!$B$6:$C$34,2,FALSE) -> General | D32: 45106 | F32: Corporate Key Gen2612
A33: EOY ASIC FY22 | B33: EOY ASIC | C33: =VLOOKUP(B33,'Document Type'!$B$6:$C$34,2,FALSE) -> General | D33: 44651 | F33: EOY ASIC FY22 Gen2612
A34: EOY ASIC FY24 | B34: EOY ASIC | C34: =VLOOKUP(B34,'Document Type'!$B$6:$C$34,2,FALSE) -> General | D34: 45473 | F34: EOY ASIC FY24 Gen2612
A35: EOY ASIC FY243 | B35: EOY ASIC | C35: =VLOOKUP(B35,'Document Type'!$B$6:$C$34,2,FALSE) -> General | D35: 45107 | F35: EOY ASIC FY23 Gen2612
A36: EOY ATO FY23 | B36: EOY ATO | C36: =VLOOKUP(B36,'Document Type'!$B$6:$C$34,2,FALSE) -> General | D36: 45107 | F36: EOY ATO FY23 Gen2612
A37: EOY ATO FY24 | B37: EOY ATO | C37: =VLOOKUP(B37,'Document Type'!$B$6:$C$34,2,FALSE) -> General | D37: 45473 | F37: EOY ATO FY24 Gen2612
A38: EOY NAB 767243550 FY22 | B38: Bank Statements | C38: =VLOOKUP(B38,'Document Type'!$B$6:$C$34,2,FALSE) -> General | D38: 45562 | F38: EOY NAB 767243550 FY22 Gen2612 | G38: Rachel
A39: EOY NAB 767243550 FY23 | B39: Bank Statements | C39: =VLOOKUP(B39,'Document Type'!$B$6:$C$34,2,FALSE) -> General | D39: 45562 | F39: EOY NAB 767243550 FY23 Gen2612 | G39: Rachel
A40: EOY NAB 767243550 FY24 | B40: Bank Statements | C40: =VLOOKUP(B40,'Document Type'!$B$6:$C$34,2,FALSE) -> General | D40: 45562 | F40: EOY NAB 767243550 FY24 Gen2612 | G40: Rachel
A41: EOY WBC 709783 FY24 | B41: Bank Statements | C41: =VLOOKUP(B41,'Document Type'!$B$6:$C$34,2,FALSE) -> General | D41: 45562 | F41: EOY WBC 709783 FY24 Gen2612 | G41: Rachel
A42: Loan Facility Deed Rachel to Gen2612 | B42: Loan Agreement | C42: =VLOOKUP(B42,'Document Type'!$B$6:$C$34,2,FALSE) -> Loans and Security | D42: 45517 | F42: In Folder Called "Rachel to Gen2612"
A43: Loan Gen2612 to Rachel | B43: Loan Agreement | C43: =VLOOKUP(B43,'Document Type'!$B$6:$C$34,2,FALSE) -> Loans and Security | D43: 44658 | F43: In Folder Called "Gen2612 to Rachel"
A44: Loan GEN2612 to Tekna | B44: Loan Agreement | C44: =VLOOKUP(B44,'Document Type'!$B$6:$C$34,2,FALSE) -> Loans and Security | D44: 45219 | F44: In Folder Called "GEN2612 to Tekna"
A45: Loan GEN2612 to THIS | B45: Loan Agreement | C45: =VLOOKUP(B45,'Document Type'!$B$6:$C$34,2,FALSE) -> Loans and Security | D45: 44713 | F45: In Folder Called "GEN2612 to THSI"
A46: Loan THFT to GEN2612 | B46: Loan Agreement | C46: =VLOOKUP(B46,'Document Type'!$B$6:$C$34,2,FALSE) -> Loans and Security | D46: 44658 | F46: In Folder called "THFT to GEN2612"
A47: Officeholder Consent | B47: Members | C47: =VLOOKUP(B47,'Document Type'!$B$6:$C$34,2,FALSE) -> Register of Members | D47: 45035 | F47: Officeholder Consent Rachel Harder Gen2612
A48: Register of Charges | B48: Members | C48: =VLOOKUP(B48,'Document Type'!$B$6:$C$34,2,FALSE) -> Register of Members | D48: 44714 | F48: Register of Charges Gen2612
...

Sheet Team Harder Super Fund
A1: All Companies
A3: Team Harder Super Fund | I3: To DO
A4: ACN: | C4: ABN: | D4: 17 209 120 631 | F4: TFN: | G4: 534 254 470
A5: Date Incorporated | E5: Shares on Issue | I5: Need to add all share purchases in assets
A6: Purpose: | E6: Is it a Trustee | F6: Yes
A7: Trust Name / Trustee
A8: Registered office | E8: Principal place of business
C9: From
A10: Current Director
A11: Current Secretary
A13: Does this Company have Loans | B13: No | E13: Is there loan documents in place | F13: No
D14: Shares | E14: Beneficially Held
A15: Current Shareholdings
A17: Current Bank Accounts | B17: Bank | C17: BSB | D17: Account | E17: Date Opened
B18: NAB Trade | C18: 083-052 | D18: 304656703 | E18: 44137
A24: Folder Storage | B24: Team Harder Super Investments | C24: Abbreviation | D24: THSF
A26: Company Register | B26: Type | C26: Folder | D26: Date | E26: Manual | F26: Electronicaly Stored | G26: By Whom
A27: SMSF Deed | B27: Trust Deed | C27: =VLOOKUP(B27,'Document Type'!$B$6:$C$34,2,FALSE) -> Trust Deed | D27: 44130 | E27: No | F27: SMSF Deed THSF | G27: Sophie Harder
A28: EOY ATO FY23 THSF | B28: EOY ATO | C28: =VLOOKUP(B28,'Document Type'!$B$6:$C$34,2,FALSE) -> General | D28: 45107 | E28: No | F28: EOY ATO FY23 THSF | G28: Sophie Harder
A29: EOY ATO FY23 040723 showing debt paid | B29: EOY ATO | C29: =VLOOKUP(B29,'Document Type'!$B$6:$C$34,2,FALSE) -> General | D29: 45111 | E29: No | F29: EOY ATO FY23 040723 THSF | G29: Sophie Harder
A30: Resolution of Members on Setup | B30: Company Setup | C30: =VLOOKUP(B30,'Document Type'!$B$6:$C$34,2,FALSE) -> Company Setup | D30: 44127 | E30: No | F30: Resolution of Members on Setup THSF | G30: Sophie Harder
A31: Formation Documents | B31: Company Setup | C31: =VLOOKUP(B31,'Document Type'!$B$6:$C$34,2,FALSE) -> Company Setup | D31: 44127 | F31: Formation Documents THSF | G31: Sophie Harder
A32: Bank Statements | B32: Bank Statements | C32: =VLOOKUP(B32,'Document Type'!$B$6:$C$34,2,FALSE) -> General | D32: 45884 | E32: No | F32: 1. WBC 727658 FY25 THSF - 11.07.24 - 11.10.24 | G32: Sophie Harder
A33: Bank Statements | B33: Bank Statements | C33: =VLOOKUP(B33,'Document Type'!$B$6:$C$34,2,FALSE) -> General | D33: 45884 | E33: No | F33: 2. WBC 727658 FY25 THSF - 11.10.24 - 10.01.25 | G33: Sophie Harder
A34: Bank Statements | B34: Bank Statements | C34: =VLOOKUP(B34,'Document Type'!$B$6:$C$34,2,FALSE) -> General | D34: 45884 | E34: No | F34: 3. WBC 727658 FY25 THSF - 10.01.25 - 11.04.25 | G34: Sophie Harder
A35: Bank Statements | B35: Bank Statements | C35: =VLOOKUP(B35,'Document Type'!$B$6:$C$34,2,FALSE) -> General | D35: 45884 | E35: No | F35: 4. WBC 727658 FY25 THSF - 11.04.25 - 11.07.25 | G35: Sophie Harder
A36: Bank Statements | B36: Bank Statements | C36: =VLOOKUP(B36,'Document Type'!$B$6:$C$34,2,FALSE) -> General | D36: 45884 | E36: No | F36: 1. WBC 727658 FY26 THSF - 11.04.25 - 11.07.25 | G36: Sophie Harder
C37: =VLOOKUP(B37,'Document Type'!$B$6:$C$34,2,FALSE) -> #N/A | E37: No
C38: =VLOOKUP(B38,'Document Type'!$B$6:$C$34,2,FALSE) -> #N/A | E38: No
C39: =VLOOKUP(B39,'Document Type'!$B$6:$C$34,2,FALSE) -> #N/A | E39: No
C40: =VLOOKUP(B40,'Document Type'!$B$6:$C$34,2,FALSE) -> #N/A | E40: No
C41: =VLOOKUP(B41,'Document Type'!$B$6:$C$34,2,FALSE) -> #N/A | E41: No
C42: =VLOOKUP(B42,'Document Type'!$B$6:$C$34,2,FALSE) -> #N/A | E42: No
C43: =VLOOKUP(B43,'Document Type'!$B$6:$C$34,2,FALSE) -> #N/A | E43: No
C44: =VLOOKUP(B44,'Document Type'!$B$6:$C$34,2,FALSE) -> #N/A | E44: No
C45: =VLOOKUP(B45,'Document Type'!$B$6:$C$34,2,FALSE) -> #N/A | E45: No
C46: =VLOOKUP(B46,'Document Type'!$B$6:$C$34,2,FALSE) -> #N/A | E46: No
C47: =VLOOKUP(B47,'Document Type'!$B$6:$C$34,2,FALSE) -> #N/A | E47: No
C48: =VLOOKUP(B48,'Document Type'!$B$6:$C$34,2,FALSE) -> #N/A | E48: No
... C61: =VLOOKUP(B61,'Document Type'!$B$6:$C$34,2,FALSE) -> #N/A | E61: No
...

Sheet Team Harder
A1: All Companies
A3: Team Harder Pty Ltd | I3: To DO
A4: ACN: | B4: 645 359 495 | C4: ABN: | F4: TFN:
A5: Date Incorporated | B5: 44127 | E5: Shares on Issue | F5: 100 | I5: Need ot find paper work for robert to transfer shares to rachel
A6: Purpose: | B6: To Act as Trustee for Team Harder Super Fund | E6: Is it a Trustee | F6: Yes
A7: Trust Name / Trustee | B7: Team Harder Super Fund
A8: Registered office | B8: MAGNUS BUSINESS ADVISERS AND ACCOUNTANTS, UNIT 10 , 39 OLD CLEVELAND ROAD , CAPALABA QLD 4157 | E8: Principal place of business | F8: 160 Alperton Road, Burbank QLD 4156
C9: From
A10: Current Director | B10: Rachel Anne Harder | C10: 44127
A11: Current Secretary
A13: Does this Company have Loans | B13: Yes | E13: Is there loan documents in place | F13: Yes
D14: Shares | E14: Beneficially Held
A15: Current Shareholdings | B15: Rachel Anne Harder | D15: 100 | E15: Yes
A17: Current Bank Accounts | B17: Bank | C17: BSB | D17: Account | E17: Date Opened
B18: NAB
B19: Westpac
A24: Folder Storage | B24: Team Harder | C24: Abbreviation | D24: TH
A26: Company Register | B26: Type | C26: Folder | D26: Date | E26: Manual | F26: Electronicaly Stored | G26: By Whom
A27: EOY ASIC FY24 | B27: EOY ASIC | C27: =VLOOKUP(B27,'Document Type'!$B$6:$C$34,2,FALSE) -> General | D27: 45471 | F27: EOY ASIC FY24 | G27: Sophie Harder
A28: EOY ATO FY24 | B28: EOY ATO | C28: =VLOOKUP(B28,'Document Type'!$B$6:$C$34,2,FALSE) -> General | D28: 45471 | F28: EOY ATO FY24 | G28: Sophie Harder
A29: Resolution of Members on Setup | B29: Company Setup | C29: =VLOOKUP(B29,'Document Type'!$B$6:$C$34,2,FALSE) -> Company Setup | D29: 44127 | E29: No | F29: Resolution of Members on Setup TH | G29: Sophie Harder
A30: Certifcate of Registration | B30: Company Setup | C30: =VLOOKUP(B30,'Document Type'!$B$6:$C$34,2,FALSE) -> Company Setup | D30: 44127 | F30: Certifcate of Registration TH | G30: Sophie Harder
A31: Formation Documents | B31: Company Setup | C31: =VLOOKUP(B31,'Document Type'!$B$6:$C$34,2,FALSE) -> Company Setup | D31: 44127 | F31: Formation Documents TH | G31: Sophie Harder
A32: Minutes Company Setup | B32: Minutes | C32: =VLOOKUP(B32,'Document Type'!$B$6:$C$34,2,FALSE) -> Minutes | D32: 44127 | F32: Minutes Company Setup TH | G32: Sophie Harder
A33: Share Certifcate Rachel | B33: Members | C33: =VLOOKUP(B33,'Document Type'!$B$6:$C$34,2,FALSE) -> Register of Members | D33: 44127 | F33: Share Certifcate Rachel TH | G33: Sophie Harder
A34: Share Certifcate Robert | B34: Members | C34: =VLOOKUP(B34,'Document Type'!$B$6:$C$34,2,FALSE) -> Register of Members | D34: 44127 | F34: Share Certifcate Robert TH | G34: Sophie Harder
A35: Signed Application for Shares Robert | B35: Members | C35: =VLOOKUP(B35,'Document Type'!$B$6:$C$34,2,FALSE) -> Register of Members | D35: 44127 | F35: Signed Application for Shares Robert TH | G35: Sophie Harder
A36: Consent Rachel Director | B36: Officers | C36: =VLOOKUP(B36,'Document Type'!$B$6:$C$34,2,FALSE) -> General | D36: 44127 | F36: Consent Rachel Director TH | G36: Sophie Harder
A37: Consent Robert Director | B37: Officers | C37: =VLOOKUP(B37,'Document Type'!$B$6:$C$34,2,FALSE) -> General | D37: 44127 | F37: Consent Robert Director TH | G37: Sophie Harder
A38: Rachel ATO Declaration | B38: Company Setup | C38: =VLOOKUP(B38,'Document Type'!$B$6:$C$34,2,FALSE) -> Company Setup | D38: 44130 | F38: Rachel ATO Declaration TH | G38: Sophie Harder
A39: Robert ATO Declaration | B39: Company Setup | C39: =VLOOKUP(B39,'Document Type'!$B$6:$C$34,2,FALSE) -> Company Setup | D39: 44130 | F39: Robert ATO Declaration TH | G39: Sophie Harder
A40: Signed Application for Shares Rachel | B40: Members | C40: =VLOOKUP(B40,'Document Type'!$B$6:$C$34,2,FALSE) -> Register of Members | D40: 44127 | F40: Signed Application for Shares Rachel TH | G40: Sophie Harder
A41: Consent Company Setup | B41: Company Setup | C41: =VLOOKUP(B41,'Document Type'!$B$6:$C$34,2,FALSE) -> Company Setup | D41: 44130 | F41: Consent Company Setup TH | G41: Sophie Harder
... A50: Constitution | B50: Constitution | C50: =VLOOKUP(B50,'Document Type'!$B$6:$C$34,2,FALSE) -> Constitution | D50: 44127 | F50: Constitution TH | G50: Sophie Harder
C51: =VLOOKUP(B51,'Document Type'!$B$6:$C$34,2,FALSE) -> #N/A
C52: =VLOOKUP(B52,'Document Type'!$B$6:$C$34,2,FALSE) -> #N/A
C53: =VLOOKUP(B53,'Document Type'!$B$6:$C$34,2,FALSE) -> #N/A
C54: =VLOOKUP(B54,'Document Type'!$B$6:$C$34,2,FALSE) -> #N/A
C55: =VLOOKUP(B55,'Document Type'!$B$6:$C$34,2,FALSE) -> #N/A
C56: =VLOOKUP(B56,'Document Type'!$B$6:$C$34,2,FALSE) -> #N/A
...

Sheet Tekna Homes
A1: All Companies
A3: Tekna Homes Pty Ltd | I3: Things to Do:
A4: ACN: | B4: 658 462 732 | C4: ABN: | D4: 34 658 462 732 | F4: TFN: | G4: 605 934 180 | I4: Need Structure Group
A5: Date Incorporated | B5: 44651 | E5: Shares on Issue | F5: 400100
A6: Purpose: | E6: Is it a Trustee
A7: Trust Name
A8: Registered office | B8: 160 Alperton Road, Burbank QLD 4156 | E8: Principal place of business | F8: 160 Alperton Road, Burbank QLD 4156
C9: From
A10: Current Director | B10: Andrew Mark Clement | C10: 44875
A11: Current Secretary | B11: Andrew Mark Clement | C11: 45194
A13: Does this Company have Loans | B13: Yes | E13: Is there loan documents in place | F13: Yes
D15: Shares | E15: Beneficially Held
A16: Current Shareholdings | B16: Tekna Pty Ltd | D16: 400100 | E16: Yes
A18: Current Bank Accounts | B18: Bank | C18: BSB | D18: Account | E18: Date Opened
B19: NAB | C19: 084435 | D19: 302971208 | E19: 44697
B20: Westpac | C20: 034-076 | D20: 702733 | E20: 45301
A25: Folder Storage | B25: Tekna Homes | C25: Abbreviation | D25: TH
A27: Company Register | B27: Type | C27: Folder | D27: Date | E27: Manual | F27: Electronicaly Stored | G27: By Whom
A28: EOY ASIC FY24 | B28: EOY ASIC | C28: =VLOOKUP(B28,'Document Type'!$B$6:$C$34,2,FALSE) -> General | D28: 45471 | F28: EOY ASIC FY24 TH | G28: Sophie Harder
A29: EOY ATO FY24 TH | B29: EOY ATO | C29: =VLOOKUP(B29,'Document Type'!$B$6:$C$34,2,FALSE) -> General | D29: 45471 | F29: EOY ATO FY24 TH | G29: Sophie Harder
A30: Constituition | B30: Constitution | C30: =VLOOKUP(B30,'Document Type'!$B$6:$C$34,2,FALSE) -> Constitution | D30: 44714 | F30: Constitution Tekna Licence TH.pdf | G30: Sophie Harder
A31: ASIC Key | B31: ASIC Key | C31: =VLOOKUP(B31,'Document Type'!$B$6:$C$34,2,FALSE) -> General | D31: 45100 | F31: ASIC Key TH | G31: Sophie Harder
A32: Corporate Key | B32: Corporate Key | C32: =VLOOKUP(B32,'Document Type'!$B$6:$C$34,2,FALSE) -> General | D32: 45100 | F32: Corporate Key TH | G32: Sophie Harder
A33: EOY ASIC FY23 | B33: EOY ASIC | C33: =VLOOKUP(B33,'Document Type'!$B$6:$C$34,2,FALSE) -> General | D33: 45107 | F33: EOY ASIC FY23 TH | G33: Sophie Harder
A34: Registered Office | B34: ASIC Docs | C34: General | D34: 44698 | F34: Registered Office Multiplace TH | G34: Sophie Harder
A35: Change of Address | B35: ASIC Docs | C35: =VLOOKUP(B35,'Document Type'!$B$6:$C$34,2,FALSE) -> General | D35: 44698 | F35: Change of Business Address TH | G35: Sophie Harder
A36: ASIC Trading Name | B36: ASIC Docs | C36: =VLOOKUP(B36,'Document Type'!$B$6:$C$34,2,FALSE) -> General | D36: 45204 | F36: ASIC Trading Name TH | G36: Sophie Harder
A37: ASIC Key For Trading Name Tekna Homes | B37: ASIC Key | C37: =VLOOKUP(B37,'Document Type'!$B$6:$C$34,2,FALSE) -> General | D37: 45204 | F37: ASIC Key For Trading Name Tekna Homes TH | G37: Sophie Harder
A38: Summary | B38: Members | C38: =VLOOKUP(B38,'Document Type'!$B$6:$C$34,2,FALSE) -> Register of Members | D38: 45194 | F38: Summary TH | G38: Sophie Harder
A39: Application for Incorporation | B39: ASIC Docs | C39: =VLOOKUP(B39,'Document Type'!$B$6:$C$34,2,FALSE) -> General | D39: 44651 | F39: Application for Incorporation TH | G39: Sophie Harder
A40: Solvency Minutes | B40: Minutes | C40: =VLOOKUP(B40,'Document Type'!$B$6:$C$34,2,FALSE) -> Minutes | D40: 45016 | F40: Annual Solvency Minutes TH | G40: Sophie Harder
A41: Resolution of Members | B41: Members | C41: =VLOOKUP(B41,'Document Type'!$B$6:$C$34,2,FALSE) -> Register of Members | D41: 44714 | F41: Resolution of Members TH | G41: Sophie Harder
A42: Register of Debentures | B42: Members | C42: =VLOOKUP(B42,'Document Type'!$B$6:$C$34,2,FALSE) -> Register of Members | D42: 44714 | F42: Register of Debentures TH | G42: Sophie Harder
A43: Register of Charges | B43: Members | C43: =VLOOKUP(B43,'Document Type'!$B$6:$C$34,2,FALSE) -> Register of Members | D43: 45035 | F43: Register of Chargers TH | G43: Sophie Harder
A44: Officeholder Consent | B44: Members | C44: =VLOOKUP(B44,'Document Type'!$B$6:$C$34,2,FALSE) -> Register of Members | D44: 44714 | F44: Officeholder Consent Samuel James Harder TH | G44: Sophie Harder
A45: Register of Members | B45: Members | C45: =VLOOKUP(B45,'Document Type'!$B$6:$C$34,2,FALSE) -> Register of Members | D45: 44714 | F45: Register of Members TH | G45: Sophie Harder
A46: Application for Shares | B46: Members | C46: =VLOOKUP(B46,'Document Type'!$B$6:$C$34,2,FALSE) -> Register of Members | D46: 45035 | F46: Application for Shares TH | G46: Sophie Harder
... A56: Cabinetry Making Machinery Invoice | B56: Asset | C56: =VLOOKUP(B56,'Document Type'!$B$6:$C$34,2,FALSE) -> Assets | D56: 45600 | F56: Cabinetry Making Machinery TH | G56: Sophie Harder
C57: =VLOOKUP(B57,'Document Type'!$B$6:$C$34,2,FALSE) -> #N/A
C58: =VLOOKUP(B58,'Document Type'!$B$6:$C$34,2,FALSE) -> #N/A
...

Sheet Tekna Drafting
B1: All Companies
B3: Tekna Drafting Pty Ltd | J3: Things to Do:
B4: ACN: | C4: 159 565 849 | D4: ABN: | E4: 96 159 565 849 | G4: TFN: | H4: 938 078 821 | J4: Need Structure Group
B5: Date Incorporated | C5: 41109 | F5: Shares on Issue | G5: 100 | J5: find scanned in shared equity agreements
B6: Purpose: | C6: Loans to Tekna Group and Others and Investments | F6: Is it a Trustee | G6: No
B7: Trust Name
B8: Registered office | C8: 160 Alperton Road, Burbank QLD 4156 | F8: Principal place of business | G8: 160 Alperton Road, Burbank QLD 4156
D9: From
B10: Current Director | C10: Andrew Mark Clement | D10: 44571
B11: Current Secretary | C11: Andrew Mark Clement | D11: 44286
B13: Does this Company have Loans | C13: Yes | F13: Is there loan documents in place
E14: Shares | F14: Beneficially Held
B15: Current Shareholdings | C15: Tekna Pty Ltd | E15: 100 | F15: Yes
B17: Current Bank Accounts | C17: Bank | D17: BSB | E17: Account | F17: Date Opened
C18: NAB | D18: 084-435 | E18: 922875532 | F18: 44663
C19: Westpac | D19: 034-076 | E19: 699626 | F19: 45282
B24: Folder Storage | C24: Tekna Drafting | D24: Abbreviation | E24: TD
B26: Company Register | C26: Type | D26: Folder | E26: Date | F26: Manual | G26: Electronicaly Stored | H26: By Whom
B27: Constitution (Previous Rock Invest QLD) | C27: Constitution | D27: =VLOOKUP(C27,'Document Type'!$B$6:$C$34,2,FALSE) -> Constitution | E27: 41109 | F27: No | G27: Constitution TD | H27: Sophie Harder
B28: Company Setup | C28: Company Setup | D28: =VLOOKUP(C28,'Document Type'!$B$6:$C$34,2,FALSE) -> Company Setup | E28: 41109 | F28: No | G28: Company Setup TD | H28: Sophie Harder
B29: Register of Members Setup TD | C29: Members | D29: =VLOOKUP(C29,'Document Type'!$B$6:$C$34,2,FALSE) -> Register of Members | E29: 41109 | F29: No | G29: Register of Members Setup TD | H29: Sophie Harder
B30: Company Setup and Members Info TD | C30: Members | D30: =VLOOKUP(C30,'Document Type'!$B$6:$C$34,2,FALSE) -> Register of Members | E30: 41109 | F30: No | G30: Company Setup and Members Info TD | H30: Sophie Harder
B31: Tax File Number TD | C31: ATO Docs | D31: =VLOOKUP(C31,'Document Type'!$B$6:$C$34,2,FALSE) -> General | E31: 41114 | F31: No | G31: Tax File Number TD | H31: Sophie Harder
B32: Solvency ASIC FY13 TD | C32: Solvency ASIC | D32: =VLOOKUP(C32,'Document Type'!$B$6:$C$34,2,FALSE) -> General | E32: 41474 | F32: No | G32: Solvency ASIC FY13 TD | H32: Sophie Harder
B33: Solvency ASIC FY14 TD | C33: Solvency ASIC | D33: =VLOOKUP(C33,'Document Type'!$B$6:$C$34,2,FALSE) -> General | E33: 41839 | F33: No | G33: Solvency ASIC FY14 TD | H33: Sophie Harder
B34: Solvency ASIC FY15 TD | C34: Solvency ASIC | D34: =VLOOKUP(C34,'Document Type'!$B$6:$C$34,2,FALSE) -> General | E34: 42204 | F34: No | G34: Solvency ASIC FY15 TD | H34: Sophie Harder
B35: Solvency ASIC FY16 TD | C35: Solvency ASIC | D35: =VLOOKUP(C35,'Document Type'!$B$6:$C$34,2,FALSE) -> General | E35: 42570 | F35: No | G35: Solvency ASIC FY16 TD | H35: Sophie Harder
B36: Solvency ASIC FY17 TD | C36: Solvency ASIC | D36: =VLOOKUP(C36,'Document Type'!$B$6:$C$34,2,FALSE) -> General | E36: 42935 | F36: No | G36: Solvency ASIC FY17 TD | H36: Sophie Harder
B37: Resignation of Director AC TD | C37: Officers | D37: =VLOOKUP(C37,'Document Type'!$B$6:$C$34,2,FALSE) -> General | E37: 42978 | F37: No | G37: Resignation of Director AC TD | H37: Sophie Harder
B38: Appoint of Director JH TD | C38: Officers | D38: =VLOOKUP(C38,'Document Type'!$B$6:$C$34,2,FALSE) -> General | E38: 42978 | F38: No | G38: Appoint of Director JH TD | H38: Sophie Harder
... B80: EOY WBC 699626 FY24 | C80: Bank Statements | D80: =VLOOKUP(C80,'Document Type'!$B$6:$C$34,2,FALSE) -> General | E80: 45562 | F80: No | G80: EOY WBC 699626 FY24 TD | H80: Rachel
D81: =VLOOKUP(C81,'Document Type'!$B$6:$C$34,2,FALSE) -> #N/A | F81: No
D82: =VLOOKUP(C82,'Document Type'!$B$6:$C$34,2,FALSE) -> #N/A | F82: No
D83: =VLOOKUP(C83,'Document Type'!$B$6:$C$34,2,FALSE) -> #N/A | F83: No
D84: =VLOOKUP(C84,'Document Type'!$B$6:$C$34,2,FALSE) -> #N/A | F84: No
D85: =VLOOKUP(C85,'Document Type'!$B$6:$C$34,2,FALSE) -> #N/A | F85: No
D86: =VLOOKUP(C86,'Document Type'!$B$6:$C$34,2,FALSE) -> #N/A | F86: No
D87: =VLOOKUP(C87,'Document Type'!$B$6:$C$34,2,FALSE) -> #N/A | F87: No
B89: Register of Members
B90: Date | C90: Issue, transfer,share split, buy back or Cancelation | D90: Class of Share | E90: Certification Number | F90: Serial Number From | G90: Serial Number To | H90: Number of Shares Aquired | I90: Trf'd to / Trf'd from | J90: Amount Paid Per Share | K90: Amount Unpaid per Share | L90: Fully Paid? (Y/N) | M90: Total Number os Shares Held | N90: Total Amount paid fo the shares | O90: Are the Shares Benedicially Held | P90: Owner / Buyer / Seller | Q90: ASIC Document Number
...

Sheet Tekna Admin
B1: All Companies
B3: Tekna Admin | J3: Things to Do
B4: ACN: | C4: 673 388 424 | D4: ABN: | E4: 81 673 388 424 | G4: TFN: | H4: 518 585 770
B5: Date Incorporated | C5: 45264 | F5: Shares on Issue | G5: 100 | J5: Structure
B6: Purpose: | C6: Charges a fee to pay for all Groups expenses per Job | F6: Is it a Trustee | G6: No
B7: Trust Name
B8: Registered office | C8: 160 Alperton Road, Burbank QLD 4156 | F8: Principal place of business | G8: 160 Alperton Road, Burbank QLD 4156
D9: From
B10: Current Director | C10: Andrew Mark Clement | D10: 45264
B11: Current Secretary | C11: Andrew Mark Clement | D11: 45264
B13: Does this Company have Loans | C13: Yes | F13: Is there loan documents in place | G13: Yes
E15: Shares | F15: Beneficially Held | G15: Yes
B16: Current Shareholdings | C16: Tekna Pty Ltd | E16: 100 | F16: Yes
B18: Current Bank Accounts | C18: Bank | D18: BSB | E18: Account | F18: Date Opened
C19: NAB | D19: 083-004 | E19: 268693995 | F19: 15/12/2023
C20: Westpac | D20: 034-076 | E20: 699642 | F20: 45282
B24: Folder Storage | C24: Tekna Admin | D24: Abbreviation | E24: TA
B26: Company Register | C26: Type | D26: Folder | E26: Date | F26: Manual | G26: Electronicaly Stored | H26: By Whom
B27: Certificate Rego TA | C27: Company Setup | D27: =VLOOKUP(C27,'Document Type'!$B$6:$C$34,2,FALSE) -> Company Setup | E27: 45264 | G27: Certificate Rego TA | H27: Sophie Harder
B28: Company Setup TA | C28: Company Setup | D28: =VLOOKUP(C28,'Document Type'!$B$6:$C$34,2,FALSE) -> Company Setup | E28: 45264 | G28: Company Setup TA | H28: Sophie Harder
B29: Computer | C29: Asset | D29: =VLOOKUP(C29,'Document Type'!$B$6:$C$34,2,FALSE) -> Assets | E29: 45468 | G29: Computer TA | H29: Sophie Harder
B30: Constitution TA | C30: Constitution | D30: =VLOOKUP(C30,'Document Type'!$B$6:$C$34,2,FALSE) -> Constitution | E30: 45264 | G30: Constitution TA | H30: Sophie Harder
B31: EOY ASIC FY24 | C31: EOY ASIC | D31: =VLOOKUP(C31,'Document Type'!$B$6:$C$34,2,FALSE) -> General | E31: 45471 | G31: EOY ASIC FY24 TA | H31: Sophie Harder
B32: EOY ATO FY24 | C32: EOY ATO | D32: =VLOOKUP(C32,'Document Type'!$B$6:$C$34,2,FALSE) -> General | E32: 45471 | G32: EOY ATO FY24 TA | H32: Sophie Harder
B33: EOY NAB 268693995 FY24 | C33: Bank Statements | D33: =VLOOKUP(C33,'Document Type'!$B$6:$C$34,2,FALSE) -> General | E33: 45562 | G33: EOY NAB 268693995 FY24 TA | H33: Rachel
B34: EOY WBC 699642 FY24 | C34: Bank Statements | D34: =VLOOKUP(C34,'Document Type'!$B$6:$C$34,2,FALSE) -> General | E34: 45562 | G34: EOY WBC 699642 FY24 TA | H34: Rachel
